Workbook

Sheet README
B1: MyoLens — Effort Estimation Workbook
B2: Enam Ahorlu | CSCD602 Advanced Software Engineering | built 13 August 2026
B4: STATUS: PRIVATE PREPARATION DOCUMENT. NOT A SUBMITTED DELIVERABLE.
B5: This workbook holds the arithmetic, the same way MyoLens_PLAN_OF_RECORD.md holds the plan. The marked effort-estimation section is written fresh inside the examination window, from the SRS as it actually ends up, and the counts below are re-derived there rather than pasted. Treat this file the way you would treat revision notes.
B7: What it computes
B8: Function Point Analysis over the frozen scope, a Value Adjustment Factor over the 14 general system characteristics, a backfired KLOC figure, COCOMO 81 organic effort, a PERT range over a work breakdown, and the reconciliation between the two.
B10: How to read it
B11: Blue cells are inputs you can change. Yellow cells are the load-bearing assumptions — the backfiring ratio and the available-hours envelope. Everything black is a formula and will move when you change an input. No result is typed in.
B13: Sheets
B14: 1 FPA Every transaction and logical file counted, with the RET/DET/FTR values that set its complexity
B15: 2 VAF The 14 GSCs, each rated 0-5 with a written justification, and the adjusted count
B16: 3 COCOMO Backfiring to KLOC, then effort, schedule and staffing from COCOMO 81 organic
... B22: The O / M / P hours on sheet 4 are the only figures in this workbook that are not derived from the frozen scope — they are judgement. Read them once and adjust anything that looks wrong for how you actually work. Everything downstream recalculates.

Sheet Weights
A1: IFPUG unadjusted weights
A2: Type | B2: Low | C2: Average | D2: High
A3: ILF | B3: 7 | C3: 10 | D3: 15
A4: EIF | B4: 5 | C4: 7 | D4: 10
A5: EI | B5: 3 | C5: 4 | D5: 6
A6: EO | B6: 4 | C6: 5 | D6: 7
A7: EQ | B7: 3 | C7: 4 | D7: 6
A10: Complexity matrices (row band x column band -> complexity)
A11: Data functions (ILF, EIF): rows = RET bands 1 / 2-5 / 6+, cols = DET bands <20 / 20-50 / 51+
A12: Low | B12: Low | C12: Average
A13: Low | B13: Average | C13: High
A14: Average | B14: High | C14: High
A17: External inputs (EI): rows = FTR bands 0-1 / 2 / 3+, cols = DET bands 1-4 / 5-15 / 16+
A18: Low | B18: Low | C18: Average
A19: Low | B19: Average | C19: High
A20: Average | B20: High | C20: High
A23: Outputs and enquiries (EO, EQ): rows = FTR bands 0-1 / 2-3 / 4+, cols = DET bands 1-5 / 6-19 / 20+
A24: Low | B24: Low | C24: Average
A25: Low | B25: Average | C25: High
A26: Average | B26: High | C26: High

Sheet 1 FPA
A1: Function Point Analysis — counted from the frozen scope (plan of record sections 7, 9 and 10)
A2: Complexity is not typed in. It is looked up from the RET/DET or FTR/DET bands on the Weights sheet, so a disagreement about a count is visible as a disagreement about a number rather than a verdict.
A4: Data functions
A5: Type | B5: Function | C5: RET/FTR | D5: DET | E5: Row band | F5: Col band | G5: Complexity | H5: FP | I5: Basis
A6: ILF | B6: Users | C6: 1 | D6: 6 | E6: =IF(C6<=1,1,IF(C6<=5,2,3)) | F6: =IF(D6<20,1,IF(D6<=50,2,3)) | G6: =INDEX(Weights!$A$12:$C$14,E6,F6) | H6: =INDEX(Weights!$B$3:$D$7,MATCH(A6,Weights!$A$3:$A$7,0),MATCH(G6,Weights!$B$2:$D$2,0)) | I6: A1 / A2 — uid, email, displayName, role, createdAt, disabledAt
A7: ILF | B7: Participants | C7: 1 | D7: 9 | E7: =IF(C7<=1,1,IF(C7<=5,2,3)) | F7: =IF(D7<20,1,IF(D7<=50,2,3)) | G7: =INDEX(Weights!$A$12:$C$14,E7,F7) | H7: =INDEX(Weights!$B$3:$D$7,MATCH(A7,Weights!$A$3:$A$7,0),MATCH(G7,Weights!$B$2:$D$2,0)) | I7: B1 — code, ageBand, sex, affectedSide, notes, createdBy, createdAt, deletedAt, difficultyBand
A8: ILF | B8: Calibrations | C8: 2 | D8: 30 | E8: =IF(C8<=1,1,IF(C8<=5,2,3)) | F8: =IF(D8<20,1,IF(D8<=50,2,3)) | G8: =INDEX(Weights!$A$12:$C$14,E8,F8) | H8: =INDEX(Weights!$B$3:$D$7,MATCH(A8,Weights!$A$3:$A$7,0),MATCH(G8,Weights!$B$2:$D$2,0)) | I8: C1-C5 — record fields plus a per-task sub-record (4 tasks x 3 fields) and a 9-value envelope vector
A9: ILF | B9: Sessions | C9: 1 | D9: 16 | E9: =IF(C9<=1,1,IF(C9<=5,2,3)) | F9: =IF(D9<20,1,IF(D9<=50,2,3)) | G9: =INDEX(Weights!$A$12:$C$14,E9,F9) | H9: =INDEX(Weights!$B$3:$D$7,MATCH(A9,Weights!$A$3:$A$7,0),MATCH(G9,Weights!$B$2:$D$2,0)) | I9: D1-D8 — provenance, montage, model version and hash, prediction object, approval fields
A10: ILF | B10: Bouts | C10: 1 | D10: 11 | E10: =IF(C10<=1,1,IF(C10<=5,2,3)) | F10: =IF(D10<20,1,IF(D10<=50,2,3)) | G10: =INDEX(Weights!$A$12:$C$14,E10,F10) | H10: =INDEX(Weights!$B$3:$D$7,MATCH(A10,Weights!$A$3:$A$7,0),MATCH(G10,Weights!$B$2:$D$2,0)) | I10: D7, E3-E6 — label, window bounds, confidence, flags, excluded, originalLabel, corrected
A11: ILF | B11: Metrics | C11: 3 | D11: 34 | E11: =IF(C11<=1,1,IF(C11<=5,2,3)) | F11: =IF(D11<20,1,IF(D11<=50,2,3)) | G11: =INDEX(Weights!$A$12:$C$14,E11,F11) | H11: =INDEX(Weights!$B$3:$D$7,MATCH(A11,Weights!$A$3:$A$7,0),MATCH(G11,Weights!$B$2:$D$2,0)) | I11: F1 — 9 metrics across 4 tasks, per-task and per-channel sub-records
A12: ILF | B12: Model registry | C12: 1 | D12: 11 | E12: =IF(C12<=1,1,IF(C12<=5,2,3)) | F12: =IF(D12<20,1,IF(D12<=50,2,3)) | G12: =INDEX(Weights!$A$12:$C$14,E12,F12) | H12: =INDEX(Weights!$B$3:$D$7,MATCH(A12,Weights!$A$3:$A$7,0),MATCH(G12,Weights!$B$2:$D$2,0)) | I12: H1, H2 — version, hash, training protocol, three accuracy figures, montage contract
A13: ILF | B13: Audit log | C13: 1 | D13: 8 | E13: =IF(C13<=1,1,IF(C13<=5,2,3)) | F13: =IF(D13<20,1,IF(D13<=50,2,3)) | G13: =INDEX(Weights!$A$12:$C$14,E13,F13) | H13: =INDEX(Weights!$B$3:$D$7,MATCH(A13,Weights!$A$3:$A$7,0),MATCH(G13,Weights!$B$2:$D$2,0)) | I13: H3, E8 — actor, action, targetType, targetId, before, after, at
A14: EIF | B14: Firebase Auth identity store | C14: 1 | D14: 6 | E14: =IF(C14<=1,1,IF(C14<=5,2,3)) | F14: =IF(D14<20,1,IF(D14<=50,2,3)) | G14: =INDEX(Weights!$A$12:$C$14,E14,F14) | H14: =INDEX(Weights!$B$3:$D$7,MATCH(A14,Weights!$A$3:$A$7,0),MATCH(G14,Weights!$B$2:$D$2,0)) | I14: A1 — referenced for token verification; identity records are maintained by the platform, not by MyoLens
A15: EIF | B15: ONNX artefact set and manifest | C15: 2 | D15: 12 | E15: =IF(C15<=1,1,IF(C15<=5,2,3)) | F15: =IF(D15<20,1,IF(D15<=50,2,3)) | G15: =INDEX(Weights!$A$12:$C$14,E15,F15) | H15: =INDEX(Weights!$B$3:$D$7,MATCH(A15,Weights!$A$3:$A$7,0),MATCH(G15,Weights!$B$2:$D$2,0)) | I15: Deployment artefacts — read at cold start, never written by the application
B16: Data function points | H16: =SUM(H6:H15)
A18: Transactional functions
A19: Type | B19: Function | C19: RET/FTR | D19: DET | E19: Row band | F19: Col band | G19: Complexity | H19: FP | I19: Basis
A20: EI | B20: Create participant | C20: 2 | D20: 9 | E20: =IF(C20<=1,1,IF(C20=2,2,3)) | F20: =IF(D20<=4,1,IF(D20<=15,2,3)) | G20: =INDEX(Weights!$A$18:$C$20,E20,F20) | H20: =INDEX(Weights!$B$3:$D$7,MATCH(A20,Weights!$A$3:$A$7,0),MATCH(G20,Weights!$B$2:$D$2,0)) | I20: B1 — writes Participants, writes Audit
A21: EI | B21: Edit participant | C21: 2 | D21: 9 | E21: =IF(C21<=1,1,IF(C21=2,2,3)) | F21: =IF(D21<=4,1,IF(D21<=15,2,3)) | G21: =INDEX(Weights!$A$18:$C$20,E21,F21) | H21: =INDEX(Weights!$B$3:$D$7,MATCH(A21,Weights!$A$3:$A$7,0),MATCH(G21,Weights!$B$2:$D$2,0)) | I21: B2
A22: EI | B22: Soft-delete participant | C22: 2 | D22: 3 | E22: =IF(C22<=1,1,IF(C22=2,2,3)) | F22: =IF(D22<=4,1,IF(D22<=15,2,3)) | G22: =INDEX(Weights!$A$18:$C$20,E22,F22) | H22: =INDEX(Weights!$B$3:$D$7,MATCH(A22,Weights!$A$3:$A$7,0),MATCH(G22,Weights!$B$2:$D$2,0)) | I22: B2 — sets deletedAt, retains the audit trail
A23: EI | B23: Register calibration capture | C23: 4 | D23: 20 | E23: =IF(C23<=1,1,IF(C23=2,2,3)) | F23: =IF(D23<=4,1,IF(D23<=15,2,3)) | G23: =INDEX(Weights!$A$18:$C$20,E23,F23) | H23: =INDEX(Weights!$B$3:$D$7,MATCH(A23,Weights!$A$3:$A$7,0),MATCH(G23,Weights!$B$2:$D$2,0)) | I23: C1-C4 — Calibrations, Participants, Audit, plus the pooled training distribution for the OOD guard
A24: EI | B24: Register session upload | C24: 4 | D24: 12 | E24: =IF(C24<=1,1,IF(C24=2,2,3)) | F24: =IF(D24<=4,1,IF(D24<=15,2,3)) | G24: =INDEX(Weights!$A$18:$C$20,E24,F24) | H24: =INDEX(Weights!$B$3:$D$7,MATCH(A24,Weights!$A$3:$A$7,0),MATCH(G24,Weights!$B$2:$D$2,0)) | I24: D1-D3 — Sessions, Participants, Calibrations, Audit; montage validated server-side
A25: EI | B25: Segment session | C25: 5 | D25: 15 | E25: =IF(C25<=1,1,IF(C25=2,2,3)) | F25: =IF(D25<=4,1,IF(D25<=15,2,3)) | G25: =INDEX(Weights!$A$18:$C$20,E25,F25) | H25: =INDEX(Weights!$B$3:$D$7,MATCH(A25,Weights!$A$3:$A$7,0),MATCH(G25,Weights!$B$2:$D$2,0)) | I25: D4-D8 — the heaviest transaction: window, feature, normalise, infer, smooth, build bouts, flag
A26: EI | B26: Relabel a bout | C26: 2 | D26: 6 | E26: =IF(C26<=1,1,IF(C26=2,2,3)) | F26: =IF(D26<=4,1,IF(D26<=15,2,3)) | G26: =INDEX(Weights!$A$18:$C$20,E26,F26) | H26: =INDEX(Weights!$B$3:$D$7,MATCH(A26,Weights!$A$3:$A$7,0),MATCH(G26,Weights!$B$2:$D$2,0)) | I26: E3
A27: EI | B27: Split a bout | C27: 2 | D27: 6 | E27: =IF(C27<=1,1,IF(C27=2,2,3)) | F27: =IF(D27<=4,1,IF(D27<=15,2,3)) | G27: =INDEX(Weights!$A$18:$C$20,E27,F27) | H27: =INDEX(Weights!$B$3:$D$7,MATCH(A27,Weights!$A$3:$A$7,0),MATCH(G27,Weights!$B$2:$D$2,0)) | I27: E4
A28: EI | B28: Merge adjacent bouts | C28: 2 | D28: 6 | E28: =IF(C28<=1,1,IF(C28=2,2,3)) | F28: =IF(D28<=4,1,IF(D28<=15,2,3)) | G28: =INDEX(Weights!$A$18:$C$20,E28,F28) | H28: =INDEX(Weights!$B$3:$D$7,MATCH(A28,Weights!$A$3:$A$7,0),MATCH(G28,Weights!$B$2:$D$2,0)) | I28: E5
A29: EI | B29: Exclude a bout | C29: 2 | D29: 4 | E29: =IF(C29<=1,1,IF(C29=2,2,3)) | F29: =IF(D29<=4,1,IF(D29<=15,2,3)) | G29: =INDEX(Weights!$A$18:$C$20,E29,F29) | H29: =INDEX(Weights!$B$3:$D$7,MATCH(A29,Weights!$A$3:$A$7,0),MATCH(G29,Weights!$B$2:$D$2,0)) | I29: E6
A30: EI | B30: Approve segmentation | C30: 5 | D30: 10 | E30: =IF(C30<=1,1,IF(C30=2,2,3)) | F30: =IF(D30<=4,1,IF(D30<=15,2,3)) | G30: =INDEX(Weights!$A$18:$C$20,E30,F30) | H30: =INDEX(Weights!$B$3:$D$7,MATCH(A30,Weights!$A$3:$A$7,0),MATCH(G30,Weights!$B$2:$D$2,0)) | I30: E7 — the gate; also triggers the metrics write
A31: EI | B31: Set clinician role | C31: 2 | D31: 4 | E31: =IF(C31<=1,1,IF(C31=2,2,3)) | F31: =IF(D31<=4,1,IF(D31<=15,2,3)) | G31: =INDEX(Weights!$A$18:$C$20,E31,F31) | H31: =INDEX(Weights!$B$3:$D$7,MATCH(A31,Weights!$A$3:$A$7,0),MATCH(G31,Weights!$B$2:$D$2,0)) | I31: A4 — custom claim, effective on next token refresh
A32: EI | B32: Authenticate | C32: 1 | D32: 4 | E32: =IF(C32<=1,1,IF(C32=2,2,3)) | F32: =IF(D32<=4,1,IF(D32<=15,2,3)) | G32: =INDEX(Weights!$A$18:$C$20,E32,F32) | H32: =INDEX(Weights!$B$3:$D$7,MATCH(A32,Weights!$A$3:$A$7,0),MATCH(G32,Weights!$B$2:$D$2,0)) | I32: A1 — email and password against Firebase Auth
A33: EO | B33: Mint V4 signed upload URL | C33: 1 | D33: 5 | E33: =IF(C33<=1,1,IF(C33<=3,2,3)) | F33: =IF(D33<=5,1,IF(D33<=19,2,3)) | G33: =INDEX(Weights!$A$24:$C$26,E33,F33) | H33: =INDEX(Weights!$B$3:$D$7,MATCH(A33,Weights!$A$3:$A$7,0),MATCH(G33,Weights!$B$2:$D$2,0)) | I33: D1 — derived, signed, and sent outside the boundary
A34: EO | B34: Calibration sufficiency report | C34: 2 | D34: 14 | E34: =IF(C34<=1,1,IF(C34<=3,2,3)) | F34: =IF(D34<=5,1,IF(D34<=19,2,3)) | G34: =INDEX(Weights!$A$24:$C$26,E34,F34) | H34: =INDEX(Weights!$B$3:$D$7,MATCH(A34,Weights!$A$3:$A$7,0),MATCH(G34,Weights!$B$2:$D$2,0)) | I34: C2 — window and block counts per task against the 20-window threshold, with pass/fail
A35: EO | B35: Predicted-difficulty band | C35: 1 | D35: 4 | E35: =IF(C35<=1,1,IF(C35<=3,2,3)) | F35: =IF(D35<=5,1,IF(D35<=19,2,3)) | G35: =INDEX(Weights!$A$24:$C$26,E35,F35) | H35: =INDEX(Weights!$B$3:$D$7,MATCH(A35,Weights!$A$3:$A$7,0),MATCH(G35,Weights!$B$2:$D$2,0)) | I35: B4 — derived from the Mahalanobis distance already computed for C4
A36: EO | B36: PDF export | C36: 5 | D36: 25 | E36: =IF(C36<=1,1,IF(C36<=3,2,3)) | F36: =IF(D36<=5,1,IF(D36<=19,2,3)) | G36: =INDEX(Weights!$A$24:$C$26,E36,F36) | H36: =INDEX(Weights!$B$3:$D$7,MATCH(A36,Weights!$A$3:$A$7,0),MATCH(G36,Weights!$B$2:$D$2,0)) | I36: G1 — every field of the record plus model provenance and the intended-use statement
A37: EQ | B37: List participants | C37: 1 | D37: 8 | E37: =IF(C37<=1,1,IF(C37<=3,2,3)) | F37: =IF(D37<=5,1,IF(D37<=19,2,3)) | G37: =INDEX(Weights!$A$24:$C$26,E37,F37) | H37: =INDEX(Weights!$B$3:$D$7,MATCH(A37,Weights!$A$3:$A$7,0),MATCH(G37,Weights!$B$2:$D$2,0)) | I37: B2 — de-identified list view
A38: EQ | B38: View participant detail | C38: 4 | D38: 22 | E38: =IF(C38<=1,1,IF(C38<=3,2,3)) | F38: =IF(D38<=5,1,IF(D38<=19,2,3)) | G38: =INDEX(Weights!$A$24:$C$26,E38,F38) | H38: =INDEX(Weights!$B$3:$D$7,MATCH(A38,Weights!$A$3:$A$7,0),MATCH(G38,Weights!$B$2:$D$2,0)) | I38: B2-B4 — participant, calibration badges, session history, activity feed
A39: EQ | B39: Get active calibration | C39: 1 | D39: 12 | E39: =IF(C39<=1,1,IF(C39<=3,2,3)) | F39: =IF(D39<=5,1,IF(D39<=19,2,3)) | G39: =INDEX(Weights!$A$24:$C$26,E39,F39) | H39: =INDEX(Weights!$B$3:$D$7,MATCH(A39,Weights!$A$3:$A$7,0),MATCH(G39,Weights!$B$2:$D$2,0)) | I39: C5
A40: EQ | B40: Get session bouts and review queue | C40: 2 | D40: 12 | E40: =IF(C40<=1,1,IF(C40<=3,2,3)) | F40: =IF(D40<=5,1,IF(D40<=19,2,3)) | G40: =INDEX(Weights!$A$24:$C$26,E40,F40) | H40: =INDEX(Weights!$B$3:$D$7,MATCH(A40,Weights!$A$3:$A$7,0),MATCH(G40,Weights!$B$2:$D$2,0)) | I40: E1, E2 — ordered ascending by confidence
A41: EQ | B41: Get metrics | C41: 2 | D41: 24 | E41: =IF(C41<=1,1,IF(C41<=3,2,3)) | F41: =IF(D41<=5,1,IF(D41<=19,2,3)) | G41: =INDEX(Weights!$A$24:$C$26,E41,F41) | H41: =INDEX(Weights!$B$3:$D$7,MATCH(A41,Weights!$A$3:$A$7,0),MATCH(G41,Weights!$B$2:$D$2,0)) | I41: F2, F4
A42: EQ | B42: Get current model card | C42: 1 | D42: 14 | E42: =IF(C42<=1,1,IF(C42<=3,2,3)) | F42: =IF(D42<=5,1,IF(D42<=19,2,3)) | G42: =INDEX(Weights!$A$24:$C$26,E42,F42) | H42: =INDEX(Weights!$B$3:$D$7,MATCH(A42,Weights!$A$3:$A$7,0),MATCH(G42,Weights!$B$2:$D$2,0)) | I42: H1
...

Sheet 2 VAF
A1: Value Adjustment Factor — the 14 general system characteristics
A2: Each rated 0 (not present) to 5 (strong influence throughout). The justification column is the part that carries the mark: a rating without a reason is a guess with a number attached.
A4: # | B4: Characteristic | C4: Rating | D4: Justification
A5: 1 | B5: Data communications | C5: 4 | D5: Browser to Cloud Run over HTTPS, and a second path from the browser direct to Cloud Storage over a signed URL. More than one communications protocol, both interactive.
A6: 2 | B6: Distributed data processing | C6: 4 | D6: Processing is genuinely distributed: the upload bypasses the API, inference runs on Cloud Run, and persistence splits between Firestore and object storage by data shape.
A7: 3 | B7: Performance | C7: 3 | D7: A stated and tested 30-second budget for a 10-minute session, with determinism pinned. Design and testing were affected; no response-time constraint drives the architecture.
A8: 4 | B8: Heavily used configuration | C8: 2 | D8: Cloud Run sized at 2 GiB against a known pandas memory transient, but there is no operational constraint from an existing installation.
A9: 5 | B9: Transaction rate | C9: 1 | D9: Deliberately low. Rate limited to 30 inferences per user per hour; batch analysis, not a transaction system.
A10: 6 | B10: Online data entry | C10: 5 | D10: Every function is interactive. There is no batch entry path anywhere in the system.
A11: 7 | B11: End-user efficiency | C11: 4 | D11: The review queue is ordered by confidence rather than time specifically to spend the clinician's attention where the model is least certain. Efficiency is a design objective, not a by-product.
A12: 8 | B12: Online update | C12: 4 | D12: All internal logical files are updated online, and the audit log makes every update recoverable in the sense of being reconstructable.
A13: 9 | B13: Complex processing | C13: 5 | D13: Extensive: 72-feature extraction with wavelet and frequency-domain terms, per-session z-scoring, a two-model soft-vote over ONNX graphs, majority-vote and minimum-dwell smoothing, a Mahalanobis out-of-distribution guard, and a co-contraction index with a defined null case.
A14: 10 | B14: Reusability | C14: 2 | D14: The model-serving boundary is designed for reuse and the next model attaches there. The application itself is not built to be reused elsewhere.
A15: 11 | B15: Installation ease | C15: 2 | D15: Deployment is automated through GitHub Actions and there is no data conversion, but installation was designed for and tested.
A16: 12 | B16: Operational ease | C16: 3 | D16: Fully managed services, no operator procedures, no manual backup or recovery. Start-up and shutdown are the platform's.
... A18: 14 | B18: Facilitate change | C18: 3 | D18: The serving runtime is swapped by configuration and the montage contract is versioned, but there are no user-maintainable queries or business rules.
B19: Total degree of influence (TDI) | C19: =SUM(C5:C18)
B20: Value adjustment factor VAF = 0.65 + 0.01 x TDI | C20: =0.65+0.01*C19
B21: Unadjusted function points (from sheet 1) | C21: ='1 FPA'!$H$47
B22: ADJUSTED FUNCTION POINTS (AFP) | C22: =ROUND(C21*C20,0)
B24: Note on the VAF itself
B25: IFPUG withdrew the VAF from the counting standard in CPM 4.3, on the grounds that the 14 characteristics overlap and are rated subjectively. It is retained here because the taught method requires it and because its range is bounded at 0.65 to 1.35 — it can move the count by a third at most, which is small beside the uncertainty in the backfiring ratio on sheet 3.

Sheet 3 COCOMO
A1: COCOMO 81 — backfired from the adjusted function point count
A2: Function points are language independent. COCOMO is not: it takes source lines. The conversion between them is the weakest link in this chain and is isolated here so it can be argued with.
B4: Backfiring to source lines
B5: Item | C5: Value | D5: Unit | F5: Basis
B6: Adjusted function points | C6: ='2 VAF'!$C$22 | D6: FP | F6: Sheet 2
B7: Share implemented server-side (Python) | C7: 0.55 | D7: of FP | F7: Every data function and the heavy transactions are server-side. Editable.
B8: Share implemented client-side (TypeScript) | C8: =1-C7 | D8: of FP | F8: Remainder.
B9: Python source lines per function point | C9: 24 | D9: LOC/FP | F9: Commonly cited backfiring table (Jones). An approximation, not a measurement.
B10: TypeScript source lines per function point | C10: 45 | D10: LOC/FP | F10: Approximated from the JavaScript figure of 47, adjusted slightly for type annotations.
B11: Blended source lines per function point | C11: =C7*C9+C8*C10 | D11: LOC/FP | F11: Share-weighted.
B12: Estimated size | C12: =C6*C11/1000 | D12: KLOC | F12: AFP x blended ratio, in thousands.
B14: The three COCOMO 81 modes, for comparison
B15: Mode | C15: a | D15: b | E15: Effort (PM) | F15: Why this mode was or was not chosen
B16: Organic | C16: 2.4 | D16: 1.05 | E16: =C16*($C$12^D16) | F16: One developer, a familiar problem domain, requirements the developer controls, no hardware coupling and no rigid external interface. Every condition Boehm sets for organic is met. CHOSEN.
B17: Semi-detached | C17: 3 | D17: 1.12 | E17: =C17*($C$12^D17) | F17: Would require a mixed-experience team and a moderate degree of external constraint. Neither applies to a single-developer project.
B18: Embedded | C18: 3.6 | D18: 1.2 | E18: =C18*($C$12^D18) | F18: Would require tight hardware, regulatory or interface constraints. MyoLens is explicitly not a medical device and has no real-time coupling.
B20: Organic result
B21: Effort E = 2.4 x KLOC^1.05 | C21: =$E$16 | D21: person-months
B22: Nominal schedule TDEV = 2.5 x E^0.38 | C22: =2.5*($E$16^0.38) | D22: months
B23: Implied average staffing E / TDEV | C23: =C21/C22 | D23: people
B24: Effort in hours (152 h per person-month) | C24: =C21*152 | D24: person-hours
B25: Available development hours in the examination | C25: 34 | D25: person-hours
B26: Available hours in total (48-hour window) | C26: 48 | D26: person-hours
B27: COCOMO effort as a multiple of the development budget | C27: =C24/C25 | D27: x
B28: COCOMO effort as a multiple of the whole window | C28: =C24/C26 | D28: x
B30: On the provenance of the coefficients
B31: The pair 2.4 and 1.05 was calibrated on 63 projects completed between 1964 and 1979, almost all of them procedural, waterfall, and written from scratch. MyoLens is component-based: a managed identity service, a managed document store, a managed runtime, a pre-trained model treated as a dependency, and a component library on the front end. COCOMO II exists precisely because that kind of construction breaks the original model's assumptions, and its Application Composition and Early Design modes are the appropriate instruments. COCOMO 81 is retained here for comparability with the taught method, with two consequences stated openly: the absolute figure is not credible, and the uncertainty is carried by the PERT range on sheet 4 rather than by this number.

Sheet 4 PERT
A1: PERT over the work breakdown — the cross-check on COCOMO
A2: E = (O + 4M + P) / 6 per leaf task; SD = (P - O) / 6. Summing expected values is valid; summing standard deviations is not, so variances are summed and the root taken at the bottom. O, M and P are in developer-hours and are the only judgement calls in this workbook — edit them.
A4: ID | B4: Task | C4: O | D4: M | E4: P | F4: Expected | G4: SD | H4: Variance | I4: Ladder | J4: Phase
A5: T01 | B5: Repository, CI skeleton and SATD register check | C5: 1 | D5: 1.5 | E5: 3 | F5: =(C5+4*D5+E5)/6 | G5: =(E5-C5)/6 | H5: =G5^2 | J5: 2 Foundations
A6: T02 | B6: First deploy: Cloud Run service and Firebase Hosting | C6: 0.5 | D6: 1 | E6: 2.5 | F6: =(C6+4*D6+E6)/6 | G6: =(E6-C6)/6 | H6: =G6^2 | J6: 2 Foundations
A7: T03 | B7: Firestore security rules and rules tests | C7: 1 | D7: 1.5 | E7: 3 | F7: =(C7+4*D7+E7)/6 | G7: =(E7-C7)/6 | H7: =G7^2 | J7: 2 Foundations
A8: T04 | B8: Auth wiring, ID-token verification, role claims | C8: 1 | D8: 2 | E8: 4 | F8: =(C8+4*D8+E8)/6 | G8: =(E8-C8)/6 | H8: =G8^2 | J8: 3 Build
A9: T05 | B9: Participant create, list, edit, soft-delete | C9: 1 | D9: 1.5 | E9: 2.5 | F9: =(C9+4*D9+E9)/6 | G9: =(E9-C9)/6 | H9: =G9^2 | J9: 3 Build
A10: T06 | B10: Admin clinician management | C10: 0.5 | D10: 0.75 | E10: 1.5 | F10: =(C10+4*D10+E10)/6 | G10: =(E10-C10)/6 | H10: =G10^2 | I10: 1 | J10: 3 Build
A11: T07 | B11: Signed-URL minting endpoint | C11: 0.5 | D11: 1 | E11: 2 | F11: =(C11+4*D11+E11)/6 | G11: =(E11-C11)/6 | H11: =G11^2 | J11: 3 Build
A12: T08 | B12: CSV ingest, montage validation, windowing | C12: 1.5 | D12: 2.5 | E12: 5 | F12: =(C12+4*D12+E12)/6 | G12: =(E12-C12)/6 | H12: =G12^2 | J12: 3 Build
A13: T09 | B13: Freq-72 feature extraction port | C13: 1 | D13: 2 | E13: 4.5 | F13: =(C13+4*D13+E13)/6 | G13: =(E13-C13)/6 | H13: =G13^2 | J13: 3 Build
A14: T10 | B14: Calibration sufficiency and percent-CAL reference | C14: 1 | D14: 1.5 | E14: 3 | F14: =(C14+4*D14+E14)/6 | G14: =(E14-C14)/6 | H14: =G14^2 | J14: 3 Build
A15: T11 | B15: OOD guard (Mahalanobis distance and threshold) | C15: 0.75 | D15: 1.25 | E15: 2.5 | F15: =(C15+4*D15+E15)/6 | G15: =(E15-C15)/6 | H15: =G15^2 | J15: 3 Build
A16: T12 | B16: Predicted-difficulty band | C16: 0.25 | D16: 0.5 | E16: 1 | F16: =(C16+4*D16+E16)/6 | G16: =(E16-C16)/6 | H16: =G16^2 | I16: 4 | J16: 3 Build
A17: T13 | B17: Predictor interface and ONNX runtime adapter | C17: 1 | D17: 1.5 | E17: 3.5 | F17: =(C17+4*D17+E17)/6 | G17: =(E17-C17)/6 | H17: =G17^2 | J17: 3 Build
A18: T14 | B18: Smoothing, bout construction and review flags | C18: 1.5 | D18: 2.5 | E18: 5 | F18: =(C18+4*D18+E18)/6 | G18: =(E18-C18)/6 | H18: =G18^2 | J18: 3 Build
A19: T15 | B19: Segmentation endpoint end to end | C19: 1 | D19: 1.5 | E19: 3 | F19: =(C19+4*D19+E19)/6 | G19: =(E19-C19)/6 | H19: =G19^2 | J19: 3 Build
A20: T16 | B20: Timeline component | C20: 2 | D20: 3 | E20: 6 | F20: =(C20+4*D20+E20)/6 | G20: =(E20-C20)/6 | H20: =G20^2 | J20: 3 Build
A21: T17 | B21: Bout list, relabel and exclude | C21: 1 | D21: 1.5 | E21: 3 | F21: =(C21+4*D21+E21)/6 | G21: =(E21-C21)/6 | H21: =G21^2 | J21: 3 Build
A22: T18 | B22: Split and merge | C22: 1 | D22: 1.5 | E22: 3.5 | F22: =(C22+4*D22+E22)/6 | G22: =(E22-C22)/6 | H22: =G22^2 | I22: 3 | J22: 3 Build
A23: T19 | B23: Approval gate and audit writes | C23: 0.75 | D23: 1.25 | E23: 2.5 | F23: =(C23+4*D23+E23)/6 | G23: =(E23-C23)/6 | H23: =G23^2 | J23: 3 Build
A24: T20 | B24: Metric computation: amplitude, duty cycle, both CCIs | C24: 1.5 | D24: 2 | E24: 4 | F24: =(C24+4*D24+E24)/6 | G24: =(E24-C24)/6 | H24: =G24^2 | J24: 3 Build
A25: T21 | B25: Results screen | C25: 1 | D25: 1.5 | E25: 3 | F25: =(C25+4*D25+E25)/6 | G25: =(E25-C25)/6 | H25: =G25^2 | J25: 3 Build
A26: T22 | B26: PDF export | C26: 1 | D26: 1.5 | E26: 3.5 | F26: =(C26+4*D26+E26)/6 | G26: =(E26-C26)/6 | H26: =G26^2 | I26: 2 | J26: 3 Build
A27: T23 | B27: Model card page and registry read | C27: 0.5 | D27: 0.75 | E27: 1.5 | F27: =(C27+4*D27+E27)/6 | G27: =(E27-C27)/6 | H27: =G27^2 | I27: 5 | J27: 3 Build
A28: T24 | B28: Rate limiting | C28: 0.25 | D28: 0.5 | E28: 1 | F28: =(C28+4*D28+E28)/6 | G28: =(E28-C28)/6 | H28: =G28^2 | I28: 6 | J28: 3 Build
A29: T25 | B29: Error boundary and refusal states | C29: 0.75 | D29: 1 | E29: 2 | F29: =(C29+4*D29+E29)/6 | G29: =(E29-C29)/6 | H29: =G29^2 | J29: 4 Hardening
A30: T26 | B30: Responsive pass and contrast check | C30: 0.5 | D30: 1 | E30: 2 | F30: =(C30+4*D30+E30)/6 | G30: =(E30-C30)/6 | H30: =G30^2 | J30: 4 Hardening
B31: MUST SET — expected effort, standard deviation | F31: =SUM(F5:F30) | G31: =SQRT(H31) | H31: =SUM(H5:H30)
B33: What the range says
B34: Available development hours | F34: ='3 COCOMO'!$C$25
B35: Expected effort, full Must set | F35: =$F$31
B36: Overrun at the expected value | F36: =$F$31-'3 COCOMO'!$C$25
B37: Probability the full Must set fits in the budget | F37: =NORMDIST('3 COCOMO'!$C$25,$F$31,$G$31,TRUE())
B38: Effort at 80 percent confidence E + 0.84 x SD | F38: =$F$31+0.84*$G$31
B39: Cone-of-uncertainty band at requirements-defined, 0.5x to 2x | F39: =$F$31*0.5 | G39: to | H39: =$F$31*2
B41: The de-scope ladder, costed
B42: The ladder in section 7 of the plan is an ordering. These are its prices. Cutting is cumulative and top-down, without renegotiation, at hour 28.
B43: Rung | C43: Item | D43: Saves (h) | E43: Cumulative saving | F43: Remaining effort | G43: Fits in budget?
...

Sheet 5 Reconciliation
B1: Reconciliation — what the two methods say, and what was done about the gap
B2: The five marks are not for producing a number. They are for noticing that the two numbers disagree by two orders of magnitude and saying what was changed as a result.
B4: The two estimates, side by side
B5: Figure | C5: Value | D5: Unit | E5: Source
B6: Unadjusted function points | C6: ='1 FPA'!$H$47 | D6: FP | E6: Sheet 1 — counted from the frozen scope
B7: Adjusted function points | C7: ='2 VAF'!$C$22 | D7: FP | E7: Sheet 2 — after the VAF
B8: COCOMO 81 organic effort | C8: ='3 COCOMO'!$C$21 | D8: person-months | E8: Sheet 3
B9: COCOMO 81 organic effort, in hours | C9: ='3 COCOMO'!$C$24 | D9: person-hours | E9: Sheet 3, at 152 h per person-month
B10: PERT expected effort, full Must set | C10: ='4 PERT'!$F$31 | D10: person-hours | E10: Sheet 4 — 26 leaf tasks
B11: PERT standard deviation | C11: ='4 PERT'!$G$31 | D11: person-hours | E11: Sheet 4 — root of summed variances
B12: Available development hours | C12: ='3 COCOMO'!$C$25 | D12: person-hours | E12: Phases 2 to 5 of the 48-hour plan
B13: COCOMO as a multiple of the development budget | C13: ='3 COCOMO'!$C$27 | D13: x
B14: COCOMO as a multiple of the whole 48-hour window | C14: ='3 COCOMO'!$C$28 | D14: x
B15: PERT probability the full Must set fits | C15: ='4 PERT'!$F$37 | E15: Normal approximation over summed variances
B16: PERT expected effort after the full de-scope ladder | C16: ='4 PERT'!$F$49 | D16: person-hours | E16: Sheet 4
B17: PERT probability the de-scoped set fits | C17: ='4 PERT'!$F$52
B19: The reconciliation, stated
B20: These sentences are built from the cells above. If an input changes they change with it, so the narrative cannot drift away from the arithmetic.
B22: ="COCOMO 81 organic returned "&TEXT('3 COCOMO'!$C$21,"0.0")&" person-months, which is "&TEXT($C$9,"#,##0")&" person-hours against the "&TEXT($C$12,"0")&" development hours the examination actually contains — a factor of "&TEXT($C$13,"0.0")&", or "&TEXT($C$14,"0.0")&" against the whole 48-hour window. That is not a scheduling problem to be worked around. It is the model telling us that the system as scoped is not a 48-hour system."
B24: ="Neither the deadline nor the team size was negotiable, so scope was the only free variable. The PERT breakdown was built to find the waterline: 26 leaf tasks, each with an optimistic, most likely and pessimistic figure, giving an expected "&TEXT($C$10,"0.0")&" hours for the full Must set against "&TEXT($C$12,"0")&" available. The probability that the full Must set fits, on a normal approximation over the summed task variances, is "&IF($C$15<0.001,"below 0.1 per cent — effectively zero",TEXT($C$15,"0.0%"))&"."
B26: ="The de-scope ladder in section 7 was therefore costed rather than merely ordered. Executing it in full — admin clinician management, PDF export, split and merge, the predicted-difficulty band, the model card page and rate limiting — recovers enough to bring expected effort to "&TEXT($C$16,"0.0")&" hours, and the probability of fitting to "&TEXT($C$17,"0.0%")&". Even fully de-scoped, the Must set does not comfortably fit."
B28: What follows from that — the three decisions the estimate actually drove
B29: 1. The five never-cut items were fixed before the ladder was costed, not after.
B30: The OOD guard, the approval gate, the audit log, the intended-use banner and montage validation carry no ladder rung and never will. Deciding that in advance is what stops a schedule overrun at hour 31 from quietly becoming an ethical one. The estimate is allowed to change what gets built; it is not allowed to change what makes the thing defensible.
B32: 2. The waterline runs through the documentation buffer, not through the never-cut set.
B33: Because the fully de-scoped set still exceeds the development envelope, the shortfall is absorbed from the 14 hours reserved for documentation and contingency rather than by cutting further into function. That is a real cost and is stated as one: the contingency is smaller than it looks on the phase plan.
B35: 3. Estimate-to-actual is logged per phase, not reconstructed at the end.
B36: Comparing the PERT figure against hours actually spent is a monitoring-and-controlling activity, and it is only possible if the actuals are recorded as they happen. The comparison itself belongs in the report — including, and especially, wherever the estimate turns out to have been wrong.
B38: Two honesty notes to carry into the write-up
B39: The plan of record's draft sentence says the overrun is 'roughly twenty times'. The arithmetic here says otherwise. That sentence was written before anything was counted and must be replaced with whatever this workbook produces on the day. A reconciliation paragraph whose multiplier does not match its own appendix is worse than no paragraph.
B41: The backfiring ratio is doing more work than any other single number in this chain. Function points are a measure of delivered function; source lines are a measure of typing. The published tables converting between them are approximations with wide dispersion, and the conversion is applied before an exponent, so its error is amplified. Say so in the report, and let the PERT range — which never touches source lines at all — be the estimate that is actually defended.
